Workbook

Sheet Без этажа
A1: Таблица воздухообменов — Без этажа | N1: Высота, м
A2: № п/п | B2: Наименование помещений | C2: Категория | D2: Температура | E2: Площадь | F2: Объём | G2: Приток кратность | H2: Вытяжка кратность | I2: Приток | J2: Вытяжка | K2: Приточная | L2: Вытяжная | M2: Примечание | N2: 3
A3: К3 | B3: Кладовая | C3: В3 | E3: 3.14 | F3: =E3*$N$2 -> 0 | I3: =F3*G3 -> 0 | J3: =F3*H3 -> 0
A4: К2 | B4: Кладовая | C4: В3 | E4: 7.24 | F4: =E4*$N$2 -> 0 | I4: =F4*G4 -> 0 | J4: =F4*H4 -> 0
A5: К1 | B5: Кладовая | C5: В3 | E5: 4.59 | F5: =E5*$N$2 -> 0 | I5: =F5*G5 -> 0 | J5: =F5*H5 -> 0
A6: К5 | B6: Кладовая | C6: В3 | E6: 4.43 | F6: =E6*$N$2 -> 0 | I6: =F6*G6 -> 0 | J6: =F6*H6 -> 0
A7: К6 | B7: Кладовая | C7: В3 | E7: 6.3 | F7: =E7*$N$2 -> 0 | I7: =F7*G7 -> 0 | J7: =F7*H7 -> 0
A8: К4 | B8: Кладовая | C8: В3 | E8: 4.18 | F8: =E8*$N$2 -> 0 | I8: =F8*G8 -> 0 | J8: =F8*H8 -> 0
A9: К7 | B9: Кладовая | C9: В3 | E9: 3.56 | F9: =E9*$N$2 -> 0 | I9: =F9*G9 -> 0 | J9: =F9*H9 -> 0
A10: К8 | B10: Кладовая | C10: В3 | E10: 3.41 | F10: =E10*$N$2 -> 0 | I10: =F10*G10 -> 0 | J10: =F10*H10 -> 0
A11: К9 | B11: Кладовая | C11: В3 | E11: 4.42 | F11: =E11*$N$2 -> 0 | I11: =F11*G11 -> 0 | J11: =F11*H11 -> 0
A12: К10 | B12: Кладовая | C12: В3 | E12: 5.58 | F12: =E12*$N$2 -> 0 | I12: =F12*G12 -> 0 | J12: =F12*H12 -> 0
A13: К11 | B13: Кладовая | C13: В3 | E13: 7.5 | F13: =E13*$N$2 -> 0 | I13: =F13*G13 -> 0 | J13: =F13*H13 -> 0
A14: К12 | B14: Кладовая | C14: В3 | E14: 5.92 | F14: =E14*$N$2 -> 0 | I14: =F14*G14 -> 0 | J14: =F14*H14 -> 0
... A82: К78 | B82: Кладовая | C82: В3 | E82: 3.68 | F82: =E82*$N$2 -> 0 | I82: =F82*G82 -> 0 | J82: =F82*H82 -> 0

Sheet Системы
A1: Система | B1: Зона обслуживания | C1: Расход м3\ч | D1: Расход с запасом м3\ч | E1: Нагрузка на калорифер кВт (расчет на расход с запасом) | F1: Размещение оборудования | G1: Выброс/забор | H1: Примечание к подборам | I1: С-ма в модели | J1: Потреи давления в с-ме, Па (аэродинамика) | K1: Потери в выбросе/заборе | L1: Потери общие | M1: Выдано на подбор производителю | N1: Установлено в модели + ХОВС | O1: Примечание
A3: - | B3: {=IFERROR(_xlfn.TEXTJOIN(", ",TRUE,_xlfn.UNIQUE(_xlfn.FILTER(_xlfn.VSTACK('Без этажа'!B3:B1000),(_xlfn.VSTACK('Без этажа'!K3:K1000)=A3)+(_xlfn.VSTACK('Без этажа'!L3:L1000)=A3)))),"Не найдено")} -> 0 | C3: {=IFERROR(SUM(_xlfn.FILTER(_xlfn.VSTACK('Без этажа'!I3:I1000),(_xlfn.VSTACK('Без этажа'!K3:K1000)=A3)+(_xlfn.VSTACK('Без этажа'!L3:L1000)=A3)))+SUM(_xlfn.FILTER(_xlfn.VSTACK('Без этажа'!J3:J1000),(_xlfn.VSTACK('Без этажа'!K3:K1000)=A3)+(_xlfn.VSTACK('Без этажа'!L3:L1000)=A3))),0)} -> 0 | D3: =C3*1.1 -> 0 | E3: {=IFERROR(SUM(_xlfn.FILTER((_xlfn.VSTACK('Без этажа'!D3:D1000)*1.005*((_xlfn.VSTACK('Без этажа'!D3:D1000))-(-32))*1.2/3600),(_xlfn.VSTACK('Без этажа'!K3:K1000)=A3)+(_xlfn.VSTACK('Без этажа'!L3:L1000)=A3))),0)} -> 0 | L3: =J3+K3 -> 0
A4: - | B4: {=IFERROR(_xlfn.TEXTJOIN(", ",TRUE,_xlfn.UNIQUE(_xlfn.FILTER(_xlfn.VSTACK('Без этажа'!B3:B1000),(_xlfn.VSTACK('Без этажа'!K3:K1000)=A4)+(_xlfn.VSTACK('Без этажа'!L3:L1000)=A4)))),"Не найдено")} -> 0 | C4: {=IFERROR(SUM(_xlfn.FILTER(_xlfn.VSTACK('Без этажа'!I3:I1000),(_xlfn.VSTACK('Без этажа'!K3:K1000)=A4)+(_xlfn.VSTACK('Без этажа'!L3:L1000)=A4)))+SUM(_xlfn.FILTER(_xlfn.VSTACK('Без этажа'!J3:J1000),(_xlfn.VSTACK('Без этажа'!K3:K1000)=A4)+(_xlfn.VSTACK('Без этажа'!L3:L1000)=A4))),0)} -> 0 | D4: =C4*1.1 -> 0 | E4: {=IFERROR(SUM(_xlfn.FILTER((_xlfn.VSTACK('Без этажа'!D3:D1000)*1.005*((_xlfn.VSTACK('Без этажа'!D3:D1000))-(-32))*1.2/3600),(_xlfn.VSTACK('Без этажа'!K3:K1000)=A4)+(_xlfn.VSTACK('Без этажа'!L3:L1000)=A4))),0)} -> 0 | L4: =J4+K4 -> 0
A5: - | B5: {=IFERROR(_xlfn.TEXTJOIN(", ",TRUE,_xlfn.UNIQUE(_xlfn.FILTER(_xlfn.VSTACK('Без этажа'!B3:B1000),(_xlfn.VSTACK('Без этажа'!K3:K1000)=A5)+(_xlfn.VSTACK('Без этажа'!L3:L1000)=A5)))),"Не найдено")} -> 0 | C5: {=IFERROR(SUM(_xlfn.FILTER(_xlfn.VSTACK('Без этажа'!I3:I1000),(_xlfn.VSTACK('Без этажа'!K3:K1000)=A5)+(_xlfn.VSTACK('Без этажа'!L3:L1000)=A5)))+SUM(_xlfn.FILTER(_xlfn.VSTACK('Без этажа'!J3:J1000),(_xlfn.VSTACK('Без этажа'!K3:K1000)=A5)+(_xlfn.VSTACK('Без этажа'!L3:L1000)=A5))),0)} -> 0 | D5: =C5*1.1 -> 0 | E5: {=IFERROR(SUM(_xlfn.FILTER((_xlfn.VSTACK('Без этажа'!D3:D1000)*1.005*((_xlfn.VSTACK('Без этажа'!D3:D1000))-(-32))*1.2/3600),(_xlfn.VSTACK('Без этажа'!K3:K1000)=A5)+(_xlfn.VSTACK('Без этажа'!L3:L1000)=A5))),0)} -> 0 | L5: =J5+K5 -> 0
A6: - | B6: {=IFERROR(_xlfn.TEXTJOIN(", ",TRUE,_xlfn.UNIQUE(_xlfn.FILTER(_xlfn.VSTACK('Без этажа'!B3:B1000),(_xlfn.VSTACK('Без этажа'!K3:K1000)=A6)+(_xlfn.VSTACK('Без этажа'!L3:L1000)=A6)))),"Не найдено")} -> 0 | C6: {=IFERROR(SUM(_xlfn.FILTER(_xlfn.VSTACK('Без этажа'!I3:I1000),(_xlfn.VSTACK('Без этажа'!K3:K1000)=A6)+(_xlfn.VSTACK('Без этажа'!L3:L1000)=A6)))+SUM(_xlfn.FILTER(_xlfn.VSTACK('Без этажа'!J3:J1000),(_xlfn.VSTACK('Без этажа'!K3:K1000)=A6)+(_xlfn.VSTACK('Без этажа'!L3:L1000)=A6))),0)} -> 0 | D6: =C6*1.1 -> 0 | E6: {=IFERROR(SUM(_xlfn.FILTER((_xlfn.VSTACK('Без этажа'!D3:D1000)*1.005*((_xlfn.VSTACK('Без этажа'!D3:D1000))-(-32))*1.2/3600),(_xlfn.VSTACK('Без этажа'!K3:K1000)=A6)+(_xlfn.VSTACK('Без этажа'!L3:L1000)=A6))),0)} -> 0 | L6: =J6+K6 -> 0
A7: - | B7: {=IFERROR(_xlfn.TEXTJOIN(", ",TRUE,_xlfn.UNIQUE(_xlfn.FILTER(_xlfn.VSTACK('Без этажа'!B3:B1000),(_xlfn.VSTACK('Без этажа'!K3:K1000)=A7)+(_xlfn.VSTACK('Без этажа'!L3:L1000)=A7)))),"Не найдено")} -> 0 | C7: {=IFERROR(SUM(_xlfn.FILTER(_xlfn.VSTACK('Без этажа'!I3:I1000),(_xlfn.VSTACK('Без этажа'!K3:K1000)=A7)+(_xlfn.VSTACK('Без этажа'!L3:L1000)=A7)))+SUM(_xlfn.FILTER(_xlfn.VSTACK('Без этажа'!J3:J1000),(_xlfn.VSTACK('Без этажа'!K3:K1000)=A7)+(_xlfn.VSTACK('Без этажа'!L3:L1000)=A7))),0)} -> 0 | D7: =C7*1.1 -> 0 | E7: {=IFERROR(SUM(_xlfn.FILTER((_xlfn.VSTACK('Без этажа'!D3:D1000)*1.005*((_xlfn.VSTACK('Без этажа'!D3:D1000))-(-32))*1.2/3600),(_xlfn.VSTACK('Без этажа'!K3:K1000)=A7)+(_xlfn.VSTACK('Без этажа'!L3:L1000)=A7))),0)} -> 0 | L7: =J7+K7 -> 0
A8: - | B8: {=IFERROR(_xlfn.TEXTJOIN(", ",TRUE,_xlfn.UNIQUE(_xlfn.FILTER(_xlfn.VSTACK('Без этажа'!B3:B1000),(_xlfn.VSTACK('Без этажа'!K3:K1000)=A8)+(_xlfn.VSTACK('Без этажа'!L3:L1000)=A8)))),"Не найдено")} -> 0 | C8: {=IFERROR(SUM(_xlfn.FILTER(_xlfn.VSTACK('Без этажа'!I3:I1000),(_xlfn.VSTACK('Без этажа'!K3:K1000)=A8)+(_xlfn.VSTACK('Без этажа'!L3:L1000)=A8)))+SUM(_xlfn.FILTER(_xlfn.VSTACK('Без этажа'!J3:J1000),(_xlfn.VSTACK('Без этажа'!K3:K1000)=A8)+(_xlfn.VSTACK('Без этажа'!L3:L1000)=A8))),0)} -> 0 | D8: =C8*1.1 -> 0 | E8: {=IFERROR(SUM(_xlfn.FILTER((_xlfn.VSTACK('Без этажа'!D3:D1000)*1.005*((_xlfn.VSTACK('Без этажа'!D3:D1000))-(-32))*1.2/3600),(_xlfn.VSTACK('Без этажа'!K3:K1000)=A8)+(_xlfn.VSTACK('Без этажа'!L3:L1000)=A8))),0)} -> 0 | L8: =J8+K8 -> 0
A9: - | B9: {=IFERROR(_xlfn.TEXTJOIN(", ",TRUE,_xlfn.UNIQUE(_xlfn.FILTER(_xlfn.VSTACK('Без этажа'!B3:B1000),(_xlfn.VSTACK('Без этажа'!K3:K1000)=A9)+(_xlfn.VSTACK('Без этажа'!L3:L1000)=A9)))),"Не найдено")} -> 0 | C9: {=IFERROR(SUM(_xlfn.FILTER(_xlfn.VSTACK('Без этажа'!I3:I1000),(_xlfn.VSTACK('Без этажа'!K3:K1000)=A9)+(_xlfn.VSTACK('Без этажа'!L3:L1000)=A9)))+SUM(_xlfn.FILTER(_xlfn.VSTACK('Без этажа'!J3:J1000),(_xlfn.VSTACK('Без этажа'!K3:K1000)=A9)+(_xlfn.VSTACK('Без этажа'!L3:L1000)=A9))),0)} -> 0 | D9: =C9*1.1 -> 0 | E9: {=IFERROR(SUM(_xlfn.FILTER((_xlfn.VSTACK('Без этажа'!D3:D1000)*1.005*((_xlfn.VSTACK('Без этажа'!D3:D1000))-(-32))*1.2/3600),(_xlfn.VSTACK('Без этажа'!K3:K1000)=A9)+(_xlfn.VSTACK('Без этажа'!L3:L1000)=A9))),0)} -> 0 | L9: =J9+K9 -> 0
A10: - | B10: {=IFERROR(_xlfn.TEXTJOIN(", ",TRUE,_xlfn.UNIQUE(_xlfn.FILTER(_xlfn.VSTACK('Без этажа'!B3:B1000),(_xlfn.VSTACK('Без этажа'!K3:K1000)=A10)+(_xlfn.VSTACK('Без этажа'!L3:L1000)=A10)))),"Не найдено")} -> 0 | C10: {=IFERROR(SUM(_xlfn.FILTER(_xlfn.VSTACK('Без этажа'!I3:I1000),(_xlfn.VSTACK('Без этажа'!K3:K1000)=A10)+(_xlfn.VSTACK('Без этажа'!L3:L1000)=A10)))+SUM(_xlfn.FILTER(_xlfn.VSTACK('Без этажа'!J3:J1000),(_xlfn.VSTACK('Без этажа'!K3:K1000)=A10)+(_xlfn.VSTACK('Без этажа'!L3:L1000)=A10))),0)} -> 0 | D10: =C10*1.1 -> 0 | E10: {=IFERROR(SUM(_xlfn.FILTER((_xlfn.VSTACK('Без этажа'!D3:D1000)*1.005*((_xlfn.VSTACK('Без этажа'!D3:D1000))-(-32))*1.2/3600),(_xlfn.VSTACK('Без этажа'!K3:K1000)=A10)+(_xlfn.VSTACK('Без этажа'!L3:L1000)=A10))),0)} -> 0 | L10: =J10+K10 -> 0
A11: - | B11: {=IFERROR(_xlfn.TEXTJOIN(", ",TRUE,_xlfn.UNIQUE(_xlfn.FILTER(_xlfn.VSTACK('Без этажа'!B3:B1000),(_xlfn.VSTACK('Без этажа'!K3:K1000)=A11)+(_xlfn.VSTACK('Без этажа'!L3:L1000)=A11)))),"Не найдено")} -> 0 | C11: {=IFERROR(SUM(_xlfn.FILTER(_xlfn.VSTACK('Без этажа'!I3:I1000),(_xlfn.VSTACK('Без этажа'!K3:K1000)=A11)+(_xlfn.VSTACK('Без этажа'!L3:L1000)=A11)))+SUM(_xlfn.FILTER(_xlfn.VSTACK('Без этажа'!J3:J1000),(_xlfn.VSTACK('Без этажа'!K3:K1000)=A11)+(_xlfn.VSTACK('Без этажа'!L3:L1000)=A11))),0)} -> 0 | D11: =C11*1.1 -> 0 | E11: {=IFERROR(SUM(_xlfn.FILTER((_xlfn.VSTACK('Без этажа'!D3:D1000)*1.005*((_xlfn.VSTACK('Без этажа'!D3:D1000))-(-32))*1.2/3600),(_xlfn.VSTACK('Без этажа'!K3:K1000)=A11)+(_xlfn.VSTACK('Без этажа'!L3:L1000)=A11))),0)} -> 0 | L11: =J11+K11 -> 0
A12: - | B12: {=IFERROR(_xlfn.TEXTJOIN(", ",TRUE,_xlfn.UNIQUE(_xlfn.FILTER(_xlfn.VSTACK('Без этажа'!B3:B1000),(_xlfn.VSTACK('Без этажа'!K3:K1000)=A12)+(_xlfn.VSTACK('Без этажа'!L3:L1000)=A12)))),"Не найдено")} -> 0 | C12: {=IFERROR(SUM(_xlfn.FILTER(_xlfn.VSTACK('Без этажа'!I3:I1000),(_xlfn.VSTACK('Без этажа'!K3:K1000)=A12)+(_xlfn.VSTACK('Без этажа'!L3:L1000)=A12)))+SUM(_xlfn.FILTER(_xlfn.VSTACK('Без этажа'!J3:J1000),(_xlfn.VSTACK('Без этажа'!K3:K1000)=A12)+(_xlfn.VSTACK('Без этажа'!L3:L1000)=A12))),0)} -> 0 | D12: =C12*1.1 -> 0 | E12: {=IFERROR(SUM(_xlfn.FILTER((_xlfn.VSTACK('Без этажа'!D3:D1000)*1.005*((_xlfn.VSTACK('Без этажа'!D3:D1000))-(-32))*1.2/3600),(_xlfn.VSTACK('Без этажа'!K3:K1000)=A12)+(_xlfn.VSTACK('Без этажа'!L3:L1000)=A12))),0)} -> 0 | L12: =J12+K12 -> 0
A13: - | B13: {=IFERROR(_xlfn.TEXTJOIN(", ",TRUE,_xlfn.UNIQUE(_xlfn.FILTER(_xlfn.VSTACK('Без этажа'!B3:B1000),(_xlfn.VSTACK('Без этажа'!K3:K1000)=A13)+(_xlfn.VSTACK('Без этажа'!L3:L1000)=A13)))),"Не найдено")} -> 0 | C13: {=IFERROR(SUM(_xlfn.FILTER(_xlfn.VSTACK('Без этажа'!I3:I1000),(_xlfn.VSTACK('Без этажа'!K3:K1000)=A13)+(_xlfn.VSTACK('Без этажа'!L3:L1000)=A13)))+SUM(_xlfn.FILTER(_xlfn.VSTACK('Без этажа'!J3:J1000),(_xlfn.VSTACK('Без этажа'!K3:K1000)=A13)+(_xlfn.VSTACK('Без этажа'!L3:L1000)=A13))),0)} -> 0 | D13: =C13*1.1 -> 0 | E13: {=IFERROR(SUM(_xlfn.FILTER((_xlfn.VSTACK('Без этажа'!D3:D1000)*1.005*((_xlfn.VSTACK('Без этажа'!D3:D1000))-(-32))*1.2/3600),(_xlfn.VSTACK('Без этажа'!K3:K1000)=A13)+(_xlfn.VSTACK('Без этажа'!L3:L1000)=A13))),0)} -> 0 | L13: =J13+K13 -> 0
A14: - | B14: {=IFERROR(_xlfn.TEXTJOIN(", ",TRUE,_xlfn.UNIQUE(_xlfn.FILTER(_xlfn.VSTACK('Без этажа'!B3:B1000),(_xlfn.VSTACK('Без этажа'!K3:K1000)=A14)+(_xlfn.VSTACK('Без этажа'!L3:L1000)=A14)))),"Не найдено")} -> 0 | C14: {=IFERROR(SUM(_xlfn.FILTER(_xlfn.VSTACK('Без этажа'!I3:I1000),(_xlfn.VSTACK('Без этажа'!K3:K1000)=A14)+(_xlfn.VSTACK('Без этажа'!L3:L1000)=A14)))+SUM(_xlfn.FILTER(_xlfn.VSTACK('Без этажа'!J3:J1000),(_xlfn.VSTACK('Без этажа'!K3:K1000)=A14)+(_xlfn.VSTACK('Без этажа'!L3:L1000)=A14))),0)} -> 0 | D14: =C14*1.1 -> 0 | E14: {=IFERROR(SUM(_xlfn.FILTER((_xlfn.VSTACK('Без этажа'!D3:D1000)*1.005*((_xlfn.VSTACK('Без этажа'!D3:D1000))-(-32))*1.2/3600),(_xlfn.VSTACK('Без этажа'!K3:K1000)=A14)+(_xlfn.VSTACK('Без этажа'!L3:L1000)=A14))),0)} -> 0 | L14: =J14+K14 -> 0
A15: - | B15: {=IFERROR(_xlfn.TEXTJOIN(", ",TRUE,_xlfn.UNIQUE(_xlfn.FILTER(_xlfn.VSTACK('Без этажа'!B3:B1000),(_xlfn.VSTACK('Без этажа'!K3:K1000)=A15)+(_xlfn.VSTACK('Без этажа'!L3:L1000)=A15)))),"Не найдено")} -> 0 | C15: {=IFERROR(SUM(_xlfn.FILTER(_xlfn.VSTACK('Без этажа'!I3:I1000),(_xlfn.VSTACK('Без этажа'!K3:K1000)=A15)+(_xlfn.VSTACK('Без этажа'!L3:L1000)=A15)))+SUM(_xlfn.FILTER(_xlfn.VSTACK('Без этажа'!J3:J1000),(_xlfn.VSTACK('Без этажа'!K3:K1000)=A15)+(_xlfn.VSTACK('Без этажа'!L3:L1000)=A15))),0)} -> 0 | D15: =C15*1.1 -> 0 | E15: {=IFERROR(SUM(_xlfn.FILTER((_xlfn.VSTACK('Без этажа'!D3:D1000)*1.005*((_xlfn.VSTACK('Без этажа'!D3:D1000))-(-32))*1.2/3600),(_xlfn.VSTACK('Без этажа'!K3:K1000)=A15)+(_xlfn.VSTACK('Без этажа'!L3:L1000)=A15))),0)} -> 0 | L15: =J15+K15 -> 0
A16: - | B16: {=IFERROR(_xlfn.TEXTJOIN(", ",TRUE,_xlfn.UNIQUE(_xlfn.FILTER(_xlfn.VSTACK('Без этажа'!B3:B1000),(_xlfn.VSTACK('Без этажа'!K3:K1000)=A16)+(_xlfn.VSTACK('Без этажа'!L3:L1000)=A16)))),"Не найдено")} -> 0 | C16: {=IFERROR(SUM(_xlfn.FILTER(_xlfn.VSTACK('Без этажа'!I3:I1000),(_xlfn.VSTACK('Без этажа'!K3:K1000)=A16)+(_xlfn.VSTACK('Без этажа'!L3:L1000)=A16)))+SUM(_xlfn.FILTER(_xlfn.VSTACK('Без этажа'!J3:J1000),(_xlfn.VSTACK('Без этажа'!K3:K1000)=A16)+(_xlfn.VSTACK('Без этажа'!L3:L1000)=A16))),0)} -> 0 | D16: =C16*1.1 -> 0 | E16: {=IFERROR(SUM(_xlfn.FILTER((_xlfn.VSTACK('Без этажа'!D3:D1000)*1.005*((_xlfn.VSTACK('Без этажа'!D3:D1000))-(-32))*1.2/3600),(_xlfn.VSTACK('Без этажа'!K3:K1000)=A16)+(_xlfn.VSTACK('Без этажа'!L3:L1000)=A16))),0)} -> 0 | L16: =J16+K16 -> 0
A17: - | B17: {=IFERROR(_xlfn.TEXTJOIN(", ",TRUE,_xlfn.UNIQUE(_xlfn.FILTER(_xlfn.VSTACK('Без этажа'!B3:B1000),(_xlfn.VSTACK('Без этажа'!K3:K1000)=A17)+(_xlfn.VSTACK('Без этажа'!L3:L1000)=A17)))),"Не найдено")} -> 0 | C17: {=IFERROR(SUM(_xlfn.FILTER(_xlfn.VSTACK('Без этажа'!I3:I1000),(_xlfn.VSTACK('Без этажа'!K3:K1000)=A17)+(_xlfn.VSTACK('Без этажа'!L3:L1000)=A17)))+SUM(_xlfn.FILTER(_xlfn.VSTACK('Без этажа'!J3:J1000),(_xlfn.VSTACK('Без этажа'!K3:K1000)=A17)+(_xlfn.VSTACK('Без этажа'!L3:L1000)=A17))),0)} -> 0 | D17: =C17*1.1 -> 0 | E17: {=IFERROR(SUM(_xlfn.FILTER((_xlfn.VSTACK('Без этажа'!D3:D1000)*1.005*((_xlfn.VSTACK('Без этажа'!D3:D1000))-(-32))*1.2/3600),(_xlfn.VSTACK('Без этажа'!K3:K1000)=A17)+(_xlfn.VSTACK('Без этажа'!L3:L1000)=A17))),0)} -> 0 | L17: =J17+K17 -> 0
A18: - | B18: {=IFERROR(_xlfn.TEXTJOIN(", ",TRUE,_xlfn.UNIQUE(_xlfn.FILTER(_xlfn.VSTACK('Без этажа'!B3:B1000),(_xlfn.VSTACK('Без этажа'!K3:K1000)=A18)+(_xlfn.VSTACK('Без этажа'!L3:L1000)=A18)))),"Не найдено")} -> 0 | C18: {=IFERROR(SUM(_xlfn.FILTER(_xlfn.VSTACK('Без этажа'!I3:I1000),(_xlfn.VSTACK('Без этажа'!K3:K1000)=A18)+(_xlfn.VSTACK('Без этажа'!L3:L1000)=A18)))+SUM(_xlfn.FILTER(_xlfn.VSTACK('Без этажа'!J3:J1000),(_xlfn.VSTACK('Без этажа'!K3:K1000)=A18)+(_xlfn.VSTACK('Без этажа'!L3:L1000)=A18))),0)} -> 0 | D18: =C18*1.1 -> 0 | E18: {=IFERROR(SUM(_xlfn.FILTER((_xlfn.VSTACK('Без этажа'!D3:D1000)*1.005*((_xlfn.VSTACK('Без этажа'!D3:D1000))-(-32))*1.2/3600),(_xlfn.VSTACK('Без этажа'!K3:K1000)=A18)+(_xlfn.VSTACK('Без этажа'!L3:L1000)=A18))),0)} -> 0 | L18: =J18+K18 -> 0
A19: - | B19: {=IFERROR(_xlfn.TEXTJOIN(", ",TRUE,_xlfn.UNIQUE(_xlfn.FILTER(_xlfn.VSTACK('Без этажа'!B3:B1000),(_xlfn.VSTACK('Без этажа'!K3:K1000)=A19)+(_xlfn.VSTACK('Без этажа'!L3:L1000)=A19)))),"Не найдено")} -> 0 | C19: {=IFERROR(SUM(_xlfn.FILTER(_xlfn.VSTACK('Без этажа'!I3:I1000),(_xlfn.VSTACK('Без этажа'!K3:K1000)=A19)+(_xlfn.VSTACK('Без этажа'!L3:L1000)=A19)))+SUM(_xlfn.FILTER(_xlfn.VSTACK('Без этажа'!J3:J1000),(_xlfn.VSTACK('Без этажа'!K3:K1000)=A19)+(_xlfn.VSTACK('Без этажа'!L3:L1000)=A19))),0)} -> 0 | D19: =C19*1.1 -> 0 | E19: {=IFERROR(SUM(_xlfn.FILTER((_xlfn.VSTACK('Без этажа'!D3:D1000)*1.005*((_xlfn.VSTACK('Без этажа'!D3:D1000))-(-32))*1.2/3600),(_xlfn.VSTACK('Без этажа'!K3:K1000)=A19)+(_xlfn.VSTACK('Без этажа'!L3:L1000)=A19))),0)} -> 0 | L19: =J19+K19 -> 0
A20: - | B20: {=IFERROR(_xlfn.TEXTJOIN(", ",TRUE,_xlfn.UNIQUE(_xlfn.FILTER(_xlfn.VSTACK('Без этажа'!B3:B1000),(_xlfn.VSTACK('Без этажа'!K3:K1000)=A20)+(_xlfn.VSTACK('Без этажа'!L3:L1000)=A20)))),"Не найдено")} -> 0 | C20: {=IFERROR(SUM(_xlfn.FILTER(_xlfn.VSTACK('Без этажа'!I3:I1000),(_xlfn.VSTACK('Без этажа'!K3:K1000)=A20)+(_xlfn.VSTACK('Без этажа'!L3:L1000)=A20)))+SUM(_xlfn.FILTER(_xlfn.VSTACK('Без этажа'!J3:J1000),(_xlfn.VSTACK('Без этажа'!K3:K1000)=A20)+(_xlfn.VSTACK('Без этажа'!L3:L1000)=A20))),0)} -> 0 | D20: =C20*1.1 -> 0 | E20: {=IFERROR(SUM(_xlfn.FILTER((_xlfn.VSTACK('Без этажа'!D3:D1000)*1.005*((_xlfn.VSTACK('Без этажа'!D3:D1000))-(-32))*1.2/3600),(_xlfn.VSTACK('Без этажа'!K3:K1000)=A20)+(_xlfn.VSTACK('Без этажа'!L3:L1000)=A20))),0)} -> 0 | L20: =J20+K20 -> 0
A21: - | B21: {=IFERROR(_xlfn.TEXTJOIN(", ",TRUE,_xlfn.UNIQUE(_xlfn.FILTER(_xlfn.VSTACK('Без этажа'!B3:B1000),(_xlfn.VSTACK('Без этажа'!K3:K1000)=A21)+(_xlfn.VSTACK('Без этажа'!L3:L1000)=A21)))),"Не найдено")} -> 0 | C21: {=IFERROR(SUM(_xlfn.FILTER(_xlfn.VSTACK('Без этажа'!I3:I1000),(_xlfn.VSTACK('Без этажа'!K3:K1000)=A21)+(_xlfn.VSTACK('Без этажа'!L3:L1000)=A21)))+SUM(_xlfn.FILTER(_xlfn.VSTACK('Без этажа'!J3:J1000),(_xlfn.VSTACK('Без этажа'!K3:K1000)=A21)+(_xlfn.VSTACK('Без этажа'!L3:L1000)=A21))),0)} -> 0 | D21: =C21*1.1 -> 0 | E21: {=IFERROR(SUM(_xlfn.FILTER((_xlfn.VSTACK('Без этажа'!D3:D1000)*1.005*((_xlfn.VSTACK('Без этажа'!D3:D1000))-(-32))*1.2/3600),(_xlfn.VSTACK('Без этажа'!K3:K1000)=A21)+(_xlfn.VSTACK('Без этажа'!L3:L1000)=A21))),0)} -> 0 | L21: =J21+K21 -> 0
A22: - | B22: {=IFERROR(_xlfn.TEXTJOIN(", ",TRUE,_xlfn.UNIQUE(_xlfn.FILTER(_xlfn.VSTACK('Без этажа'!B3:B1000),(_xlfn.VSTACK('Без этажа'!K3:K1000)=A22)+(_xlfn.VSTACK('Без этажа'!L3:L1000)=A22)))),"Не найдено")} -> 0 | C22: {=IFERROR(SUM(_xlfn.FILTER(_xlfn.VSTACK('Без этажа'!I3:I1000),(_xlfn.VSTACK('Без этажа'!K3:K1000)=A22)+(_xlfn.VSTACK('Без этажа'!L3:L1000)=A22)))+SUM(_xlfn.FILTER(_xlfn.VSTACK('Без этажа'!J3:J1000),(_xlfn.VSTACK('Без этажа'!K3:K1000)=A22)+(_xlfn.VSTACK('Без этажа'!L3:L1000)=A22))),0)} -> 0 | D22: =C22*1.1 -> 0 | E22: {=IFERROR(SUM(_xlfn.FILTER((_xlfn.VSTACK('Без этажа'!D3:D1000)*1.005*((_xlfn.VSTACK('Без этажа'!D3:D1000))-(-32))*1.2/3600),(_xlfn.VSTACK('Без этажа'!K3:K1000)=A22)+(_xlfn.VSTACK('Без этажа'!L3:L1000)=A22))),0)} -> 0 | L22: =J22+K22 -> 0
A23: - | B23: {=IFERROR(_xlfn.TEXTJOIN(", ",TRUE,_xlfn.UNIQUE(_xlfn.FILTER(_xlfn.VSTACK('Без этажа'!B3:B1000),(_xlfn.VSTACK('Без этажа'!K3:K1000)=A23)+(_xlfn.VSTACK('Без этажа'!L3:L1000)=A23)))),"Не найдено")} -> 0 | C23: {=IFERROR(SUM(_xlfn.FILTER(_xlfn.VSTACK('Без этажа'!I3:I1000),(_xlfn.VSTACK('Без этажа'!K3:K1000)=A23)+(_xlfn.VSTACK('Без этажа'!L3:L1000)=A23)))+SUM(_xlfn.FILTER(_xlfn.VSTACK('Без этажа'!J3:J1000),(_xlfn.VSTACK('Без этажа'!K3:K1000)=A23)+(_xlfn.VSTACK('Без этажа'!L3:L1000)=A23))),0)} -> 0 | D23: =C23*1.1 -> 0 | E23: {=IFERROR(SUM(_xlfn.FILTER((_xlfn.VSTACK('Без этажа'!D3:D1000)*1.005*((_xlfn.VSTACK('Без этажа'!D3:D1000))-(-32))*1.2/3600),(_xlfn.VSTACK('Без этажа'!K3:K1000)=A23)+(_xlfn.VSTACK('Без этажа'!L3:L1000)=A23))),0)} -> 0 | L23: =J23+K23 -> 0
A24: - | B24: {=IFERROR(_xlfn.TEXTJOIN(", ",TRUE,_xlfn.UNIQUE(_xlfn.FILTER(_xlfn.VSTACK('Без этажа'!B3:B1000),(_xlfn.VSTACK('Без этажа'!K3:K1000)=A24)+(_xlfn.VSTACK('Без этажа'!L3:L1000)=A24)))),"Не найдено")} -> 0 | C24: {=IFERROR(SUM(_xlfn.FILTER(_xlfn.VSTACK('Без этажа'!I3:I1000),(_xlfn.VSTACK('Без этажа'!K3:K1000)=A24)+(_xlfn.VSTACK('Без этажа'!L3:L1000)=A24)))+SUM(_xlfn.FILTER(_xlfn.VSTACK('Без этажа'!J3:J1000),(_xlfn.VSTACK('Без этажа'!K3:K1000)=A24)+(_xlfn.VSTACK('Без этажа'!L3:L1000)=A24))),0)} -> 0 | D24: =C24*1.1 -> 0 | E24: {=IFERROR(SUM(_xlfn.FILTER((_xlfn.VSTACK('Без этажа'!D3:D1000)*1.005*((_xlfn.VSTACK('Без этажа'!D3:D1000))-(-32))*1.2/3600),(_xlfn.VSTACK('Без этажа'!K3:K1000)=A24)+(_xlfn.VSTACK('Без этажа'!L3:L1000)=A24))),0)} -> 0 | L24: =J24+K24 -> 0
A25: - | B25: {=IFERROR(_xlfn.TEXTJOIN(", ",TRUE,_xlfn.UNIQUE(_xlfn.FILTER(_xlfn.VSTACK('Без этажа'!B3:B1000),(_xlfn.VSTACK('Без этажа'!K3:K1000)=A25)+(_xlfn.VSTACK('Без этажа'!L3:L1000)=A25)))),"Не найдено")} -> 0 | C25: {=IFERROR(SUM(_xlfn.FILTER(_xlfn.VSTACK('Без этажа'!I3:I1000),(_xlfn.VSTACK('Без этажа'!K3:K1000)=A25)+(_xlfn.VSTACK('Без этажа'!L3:L1000)=A25)))+SUM(_xlfn.FILTER(_xlfn.VSTACK('Без этажа'!J3:J1000),(_xlfn.VSTACK('Без этажа'!K3:K1000)=A25)+(_xlfn.VSTACK('Без этажа'!L3:L1000)=A25))),0)} -> 0 | D25: =C25*1.1 -> 0 | E25: {=IFERROR(SUM(_xlfn.FILTER((_xlfn.VSTACK('Без этажа'!D3:D1000)*1.005*((_xlfn.VSTACK('Без этажа'!D3:D1000))-(-32))*1.2/3600),(_xlfn.VSTACK('Без этажа'!K3:K1000)=A25)+(_xlfn.VSTACK('Без этажа'!L3:L1000)=A25))),0)} -> 0 | L25: =J25+K25 -> 0
A26: - | B26: {=IFERROR(_xlfn.TEXTJOIN(", ",TRUE,_xlfn.UNIQUE(_xlfn.FILTER(_xlfn.VSTACK('Без этажа'!B3:B1000),(_xlfn.VSTACK('Без этажа'!K3:K1000)=A26)+(_xlfn.VSTACK('Без этажа'!L3:L1000)=A26)))),"Не найдено")} -> 0 | C26: {=IFERROR(SUM(_xlfn.FILTER(_xlfn.VSTACK('Без этажа'!I3:I1000),(_xlfn.VSTACK('Без этажа'!K3:K1000)=A26)+(_xlfn.VSTACK('Без этажа'!L3:L1000)=A26)))+SUM(_xlfn.FILTER(_xlfn.VSTACK('Без этажа'!J3:J1000),(_xlfn.VSTACK('Без этажа'!K3:K1000)=A26)+(_xlfn.VSTACK('Без этажа'!L3:L1000)=A26))),0)} -> 0 | D26: =C26*1.1 -> 0 | E26: {=IFERROR(SUM(_xlfn.FILTER((_xlfn.VSTACK('Без этажа'!D3:D1000)*1.005*((_xlfn.VSTACK('Без этажа'!D3:D1000))-(-32))*1.2/3600),(_xlfn.VSTACK('Без этажа'!K3:K1000)=A26)+(_xlfn.VSTACK('Без этажа'!L3:L1000)=A26))),0)} -> 0 | L26: =J26+K26 -> 0
A27: - | B27: {=IFERROR(_xlfn.TEXTJOIN(", ",TRUE,_xlfn.UNIQUE(_xlfn.FILTER(_xlfn.VSTACK('Без этажа'!B3:B1000),(_xlfn.VSTACK('Без этажа'!K3:K1000)=A27)+(_xlfn.VSTACK('Без этажа'!L3:L1000)=A27)))),"Не найдено")} -> 0 | C27: {=IFERROR(SUM(_xlfn.FILTER(_xlfn.VSTACK('Без этажа'!I3:I1000),(_xlfn.VSTACK('Без этажа'!K3:K1000)=A27)+(_xlfn.VSTACK('Без этажа'!L3:L1000)=A27)))+SUM(_xlfn.FILTER(_xlfn.VSTACK('Без этажа'!J3:J1000),(_xlfn.VSTACK('Без этажа'!K3:K1000)=A27)+(_xlfn.VSTACK('Без этажа'!L3:L1000)=A27))),0)} -> 0 | D27: =C27*1.1 -> 0 | E27: {=IFERROR(SUM(_xlfn.FILTER((_xlfn.VSTACK('Без этажа'!D3:D1000)*1.005*((_xlfn.VSTACK('Без этажа'!D3:D1000))-(-32))*1.2/3600),(_xlfn.VSTACK('Без этажа'!K3:K1000)=A27)+(_xlfn.VSTACK('Без этажа'!L3:L1000)=A27))),0)} -> 0 | L27: =J27+K27 -> 0
A28: - | B28: {=IFERROR(_xlfn.TEXTJOIN(", ",TRUE,_xlfn.UNIQUE(_xlfn.FILTER(_xlfn.VSTACK('Без этажа'!B3:B1000),(_xlfn.VSTACK('Без этажа'!K3:K1000)=A28)+(_xlfn.VSTACK('Без этажа'!L3:L1000)=A28)))),"Не найдено")} -> 0 | C28: {=IFERROR(SUM(_xlfn.FILTER(_xlfn.VSTACK('Без этажа'!I3:I1000),(_xlfn.VSTACK('Без этажа'!K3:K1000)=A28)+(_xlfn.VSTACK('Без этажа'!L3:L1000)=A28)))+SUM(_xlfn.FILTER(_xlfn.VSTACK('Без этажа'!J3:J1000),(_xlfn.VSTACK('Без этажа'!K3:K1000)=A28)+(_xlfn.VSTACK('Без этажа'!L3:L1000)=A28))),0)} -> 0 | D28: =C28*1.1 -> 0 | E28: {=IFERROR(SUM(_xlfn.FILTER((_xlfn.VSTACK('Без этажа'!D3:D1000)*1.005*((_xlfn.VSTACK('Без этажа'!D3:D1000))-(-32))*1.2/3600),(_xlfn.VSTACK('Без этажа'!K3:K1000)=A28)+(_xlfn.VSTACK('Без этажа'!L3:L1000)=A28))),0)} -> 0 | L28: =J28+K28 -> 0
A29: - | B29: {=IFERROR(_xlfn.TEXTJOIN(", ",TRUE,_xlfn.UNIQUE(_xlfn.FILTER(_xlfn.VSTACK('Без этажа'!B3:B1000),(_xlfn.VSTACK('Без этажа'!K3:K1000)=A29)+(_xlfn.VSTACK('Без этажа'!L3:L1000)=A29)))),"Не найдено")} -> 0 | C29: {=IFERROR(SUM(_xlfn.FILTER(_xlfn.VSTACK('Без этажа'!I3:I1000),(_xlfn.VSTACK('Без этажа'!K3:K1000)=A29)+(_xlfn.VSTACK('Без этажа'!L3:L1000)=A29)))+SUM(_xlfn.FILTER(_xlfn.VSTACK('Без этажа'!J3:J1000),(_xlfn.VSTACK('Без этажа'!K3:K1000)=A29)+(_xlfn.VSTACK('Без этажа'!L3:L1000)=A29))),0)} -> 0 | D29: =C29*1.1 -> 0 | E29: {=IFERROR(SUM(_xlfn.FILTER((_xlfn.VSTACK('Без этажа'!D3:D1000)*1.005*((_xlfn.VSTACK('Без этажа'!D3:D1000))-(-32))*1.2/3600),(_xlfn.VSTACK('Без этажа'!K3:K1000)=A29)+(_xlfn.VSTACK('Без этажа'!L3:L1000)=A29))),0)} -> 0 | L29: =J29+K29 -> 0
A30: - | B30: {=IFERROR(_xlfn.TEXTJOIN(", ",TRUE,_xlfn.UNIQUE(_xlfn.FILTER(_xlfn.VSTACK('Без этажа'!B3:B1000),(_xlfn.VSTACK('Без этажа'!K3:K1000)=A30)+(_xlfn.VSTACK('Без этажа'!L3:L1000)=A30)))),"Не найдено")} -> 0 | C30: {=IFERROR(SUM(_xlfn.FILTER(_xlfn.VSTACK('Без этажа'!I3:I1000),(_xlfn.VSTACK('Без этажа'!K3:K1000)=A30)+(_xlfn.VSTACK('Без этажа'!L3:L1000)=A30)))+SUM(_xlfn.FILTER(_xlfn.VSTACK('Без этажа'!J3:J1000),(_xlfn.VSTACK('Без этажа'!K3:K1000)=A30)+(_xlfn.VSTACK('Без этажа'!L3:L1000)=A30))),0)} -> 0 | D30: =C30*1.1 -> 0 | E30: {=IFERROR(SUM(_xlfn.FILTER((_xlfn.VSTACK('Без этажа'!D3:D1000)*1.005*((_xlfn.VSTACK('Без этажа'!D3:D1000))-(-32))*1.2/3600),(_xlfn.VSTACK('Без этажа'!K3:K1000)=A30)+(_xlfn.VSTACK('Без этажа'!L3:L1000)=A30))),0)} -> 0 | L30: =J30+K30 -> 0
A31: - | B31: {=IFERROR(_xlfn.TEXTJOIN(", ",TRUE,_xlfn.UNIQUE(_xlfn.FILTER(_xlfn.VSTACK('Без этажа'!B3:B1000),(_xlfn.VSTACK('Без этажа'!K3:K1000)=A31)+(_xlfn.VSTACK('Без этажа'!L3:L1000)=A31)))),"Не найдено")} -> 0 | C31: {=IFERROR(SUM(_xlfn.FILTER(_xlfn.VSTACK('Без этажа'!I3:I1000),(_xlfn.VSTACK('Без этажа'!K3:K1000)=A31)+(_xlfn.VSTACK('Без этажа'!L3:L1000)=A31)))+SUM(_xlfn.FILTER(_xlfn.VSTACK('Без этажа'!J3:J1000),(_xlfn.VSTACK('Без этажа'!K3:K1000)=A31)+(_xlfn.VSTACK('Без этажа'!L3:L1000)=A31))),0)} -> 0 | D31: =C31*1.1 -> 0 | E31: {=IFERROR(SUM(_xlfn.FILTER((_xlfn.VSTACK('Без этажа'!D3:D1000)*1.005*((_xlfn.VSTACK('Без этажа'!D3:D1000))-(-32))*1.2/3600),(_xlfn.VSTACK('Без этажа'!K3:K1000)=A31)+(_xlfn.VSTACK('Без этажа'!L3:L1000)=A31))),0)} -> 0 | L31: =J31+K31 -> 0
A32: - | B32: {=IFERROR(_xlfn.TEXTJOIN(", ",TRUE,_xlfn.UNIQUE(_xlfn.FILTER(_xlfn.VSTACK('Без этажа'!B3:B1000),(_xlfn.VSTACK('Без этажа'!K3:K1000)=A32)+(_xlfn.VSTACK('Без этажа'!L3:L1000)=A32)))),"Не найдено")} -> 0 | C32: {=IFERROR(SUM(_xlfn.FILTER(_xlfn.VSTACK('Без этажа'!I3:I1000),(_xlfn.VSTACK('Без этажа'!K3:K1000)=A32)+(_xlfn.VSTACK('Без этажа'!L3:L1000)=A32)))+SUM(_xlfn.FILTER(_xlfn.VSTACK('Без этажа'!J3:J1000),(_xlfn.VSTACK('Без этажа'!K3:K1000)=A32)+(_xlfn.VSTACK('Без этажа'!L3:L1000)=A32))),0)} -> 0 | D32: =C32*1.1 -> 0 | E32: {=IFERROR(SUM(_xlfn.FILTER((_xlfn.VSTACK('Без этажа'!D3:D1000)*1.005*((_xlfn.VSTACK('Без этажа'!D3:D1000))-(-32))*1.2/3600),(_xlfn.VSTACK('Без этажа'!K3:K1000)=A32)+(_xlfn.VSTACK('Без этажа'!L3:L1000)=A32))),0)} -> 0 | L32: =J32+K32 -> 0
A33: - | B33: {=IFERROR(_xlfn.TEXTJOIN(", ",TRUE,_xlfn.UNIQUE(_xlfn.FILTER(_xlfn.VSTACK('Без этажа'!B3:B1000),(_xlfn.VSTACK('Без этажа'!K3:K1000)=A33)+(_xlfn.VSTACK('Без этажа'!L3:L1000)=A33)))),"Не найдено")} -> 0 | C33: {=IFERROR(SUM(_xlfn.FILTER(_xlfn.VSTACK('Без этажа'!I3:I1000),(_xlfn.VSTACK('Без этажа'!K3:K1000)=A33)+(_xlfn.VSTACK('Без этажа'!L3:L1000)=A33)))+SUM(_xlfn.FILTER(_xlfn.VSTACK('Без этажа'!J3:J1000),(_xlfn.VSTACK('Без этажа'!K3:K1000)=A33)+(_xlfn.VSTACK('Без этажа'!L3:L1000)=A33))),0)} -> 0 | D33: =C33*1.1 -> 0 | E33: {=IFERROR(SUM(_xlfn.FILTER((_xlfn.VSTACK('Без этажа'!D3:D1000)*1.005*((_xlfn.VSTACK('Без этажа'!D3:D1000))-(-32))*1.2/3600),(_xlfn.VSTACK('Без этажа'!K3:K1000)=A33)+(_xlfn.VSTACK('Без этажа'!L3:L1000)=A33))),0)} -> 0 | L33: =J33+K33 -> 0
A34: - | B34: {=IFERROR(_xlfn.TEXTJOIN(", ",TRUE,_xlfn.UNIQUE(_xlfn.FILTER(_xlfn.VSTACK('Без этажа'!B3:B1000),(_xlfn.VSTACK('Без этажа'!K3:K1000)=A34)+(_xlfn.VSTACK('Без этажа'!L3:L1000)=A34)))),"Не найдено")} -> 0 | C34: {=IFERROR(SUM(_xlfn.FILTER(_xlfn.VSTACK('Без этажа'!I3:I1000),(_xlfn.VSTACK('Без этажа'!K3:K1000)=A34)+(_xlfn.VSTACK('Без этажа'!L3:L1000)=A34)))+SUM(_xlfn.FILTER(_xlfn.VSTACK('Без этажа'!J3:J1000),(_xlfn.VSTACK('Без этажа'!K3:K1000)=A34)+(_xlfn.VSTACK('Без этажа'!L3:L1000)=A34))),0)} -> 0 | D34: =C34*1.1 -> 0 | E34: {=IFERROR(SUM(_xlfn.FILTER((_xlfn.VSTACK('Без этажа'!D3:D1000)*1.005*((_xlfn.VSTACK('Без этажа'!D3:D1000))-(-32))*1.2/3600),(_xlfn.VSTACK('Без этажа'!K3:K1000)=A34)+(_xlfn.VSTACK('Без этажа'!L3:L1000)=A34))),0)} -> 0 | L34: =J34+K34 -> 0
A35: - | B35: {=IFERROR(_xlfn.TEXTJOIN(", ",TRUE,_xlfn.UNIQUE(_xlfn.FILTER(_xlfn.VSTACK('Без этажа'!B3:B1000),(_xlfn.VSTACK('Без этажа'!K3:K1000)=A35)+(_xlfn.VSTACK('Без этажа'!L3:L1000)=A35)))),"Не найдено")} -> 0 | C35: {=IFERROR(SUM(_xlfn.FILTER(_xlfn.VSTACK('Без этажа'!I3:I1000),(_xlfn.VSTACK('Без этажа'!K3:K1000)=A35)+(_xlfn.VSTACK('Без этажа'!L3:L1000)=A35)))+SUM(_xlfn.FILTER(_xlfn.VSTACK('Без этажа'!J3:J1000),(_xlfn.VSTACK('Без этажа'!K3:K1000)=A35)+(_xlfn.VSTACK('Без этажа'!L3:L1000)=A35))),0)} -> 0 | D35: =C35*1.1 -> 0 | E35: {=IFERROR(SUM(_xlfn.FILTER((_xlfn.VSTACK('Без этажа'!D3:D1000)*1.005*((_xlfn.VSTACK('Без этажа'!D3:D1000))-(-32))*1.2/3600),(_xlfn.VSTACK('Без этажа'!K3:K1000)=A35)+(_xlfn.VSTACK('Без этажа'!L3:L1000)=A35))),0)} -> 0 | L35: =J35+K35 -> 0
A36: - | B36: {=IFERROR(_xlfn.TEXTJOIN(", ",TRUE,_xlfn.UNIQUE(_xlfn.FILTER(_xlfn.VSTACK('Без этажа'!B3:B1000),(_xlfn.VSTACK('Без этажа'!K3:K1000)=A36)+(_xlfn.VSTACK('Без этажа'!L3:L1000)=A36)))),"Не найдено")} -> 0 | C36: {=IFERROR(SUM(_xlfn.FILTER(_xlfn.VSTACK('Без этажа'!I3:I1000),(_xlfn.VSTACK('Без этажа'!K3:K1000)=A36)+(_xlfn.VSTACK('Без этажа'!L3:L1000)=A36)))+SUM(_xlfn.FILTER(_xlfn.VSTACK('Без этажа'!J3:J1000),(_xlfn.VSTACK('Без этажа'!K3:K1000)=A36)+(_xlfn.VSTACK('Без этажа'!L3:L1000)=A36))),0)} -> 0 | D36: =C36*1.1 -> 0 | E36: {=IFERROR(SUM(_xlfn.FILTER((_xlfn.VSTACK('Без этажа'!D3:D1000)*1.005*((_xlfn.VSTACK('Без этажа'!D3:D1000))-(-32))*1.2/3600),(_xlfn.VSTACK('Без этажа'!K3:K1000)=A36)+(_xlfn.VSTACK('Без этажа'!L3:L1000)=A36))),0)} -> 0 | L36: =J36+K36 -> 0
A37: - | B37: {=IFERROR(_xlfn.TEXTJOIN(", ",TRUE,_xlfn.UNIQUE(_xlfn.FILTER(_xlfn.VSTACK('Без этажа'!B3:B1000),(_xlfn.VSTACK('Без этажа'!K3:K1000)=A37)+(_xlfn.VSTACK('Без этажа'!L3:L1000)=A37)))),"Не найдено")} -> 0 | C37: {=IFERROR(SUM(_xlfn.FILTER(_xlfn.VSTACK('Без этажа'!I3:I1000),(_xlfn.VSTACK('Без этажа'!K3:K1000)=A37)+(_xlfn.VSTACK('Без этажа'!L3:L1000)=A37)))+SUM(_xlfn.FILTER(_xlfn.VSTACK('Без этажа'!J3:J1000),(_xlfn.VSTACK('Без этажа'!K3:K1000)=A37)+(_xlfn.VSTACK('Без этажа'!L3:L1000)=A37))),0)} -> 0 | D37: =C37*1.1 -> 0 | E37: {=IFERROR(SUM(_xlfn.FILTER((_xlfn.VSTACK('Без этажа'!D3:D1000)*1.005*((_xlfn.VSTACK('Без этажа'!D3:D1000))-(-32))*1.2/3600),(_xlfn.VSTACK('Без этажа'!K3:K1000)=A37)+(_xlfn.VSTACK('Без этажа'!L3:L1000)=A37))),0)} -> 0 | L37: =J37+K37 -> 0
A38: - | B38: {=IFERROR(_xlfn.TEXTJOIN(", ",TRUE,_xlfn.UNIQUE(_xlfn.FILTER(_xlfn.VSTACK('Без этажа'!B3:B1000),(_xlfn.VSTACK('Без этажа'!K3:K1000)=A38)+(_xlfn.VSTACK('Без этажа'!L3:L1000)=A38)))),"Не найдено")} -> 0 | C38: {=IFERROR(SUM(_xlfn.FILTER(_xlfn.VSTACK('Без этажа'!I3:I1000),(_xlfn.VSTACK('Без этажа'!K3:K1000)=A38)+(_xlfn.VSTACK('Без этажа'!L3:L1000)=A38)))+SUM(_xlfn.FILTER(_xlfn.VSTACK('Без этажа'!J3:J1000),(_xlfn.VSTACK('Без этажа'!K3:K1000)=A38)+(_xlfn.VSTACK('Без этажа'!L3:L1000)=A38))),0)} -> 0 | D38: =C38*1.1 -> 0 | E38: {=IFERROR(SUM(_xlfn.FILTER((_xlfn.VSTACK('Без этажа'!D3:D1000)*1.005*((_xlfn.VSTACK('Без этажа'!D3:D1000))-(-32))*1.2/3600),(_xlfn.VSTACK('Без этажа'!K3:K1000)=A38)+(_xlfn.VSTACK('Без этажа'!L3:L1000)=A38))),0)} -> 0 | L38: =J38+K38 -> 0
A39: - | B39: {=IFERROR(_xlfn.TEXTJOIN(", ",TRUE,_xlfn.UNIQUE(_xlfn.FILTER(_xlfn.VSTACK('Без этажа'!B3:B1000),(_xlfn.VSTACK('Без этажа'!K3:K1000)=A39)+(_xlfn.VSTACK('Без этажа'!L3:L1000)=A39)))),"Не найдено")} -> 0 | C39: {=IFERROR(SUM(_xlfn.FILTER(_xlfn.VSTACK('Без этажа'!I3:I1000),(_xlfn.VSTACK('Без этажа'!K3:K1000)=A39)+(_xlfn.VSTACK('Без этажа'!L3:L1000)=A39)))+SUM(_xlfn.FILTER(_xlfn.VSTACK('Без этажа'!J3:J1000),(_xlfn.VSTACK('Без этажа'!K3:K1000)=A39)+(_xlfn.VSTACK('Без этажа'!L3:L1000)=A39))),0)} -> 0 | D39: =C39*1.1 -> 0 | E39: {=IFERROR(SUM(_xlfn.FILTER((_xlfn.VSTACK('Без этажа'!D3:D1000)*1.005*((_xlfn.VSTACK('Без этажа'!D3:D1000))-(-32))*1.2/3600),(_xlfn.VSTACK('Без этажа'!K3:K1000)=A39)+(_xlfn.VSTACK('Без этажа'!L3:L1000)=A39))),0)} -> 0 | L39: =J39+K39 -> 0
A40: - | B40: {=IFERROR(_xlfn.TEXTJOIN(", ",TRUE,_xlfn.UNIQUE(_xlfn.FILTER(_xlfn.VSTACK('Без этажа'!B3:B1000),(_xlfn.VSTACK('Без этажа'!K3:K1000)=A40)+(_xlfn.VSTACK('Без этажа'!L3:L1000)=A40)))),"Не найдено")} -> 0 | C40: {=IFERROR(SUM(_xlfn.FILTER(_xlfn.VSTACK('Без этажа'!I3:I1000),(_xlfn.VSTACK('Без этажа'!K3:K1000)=A40)+(_xlfn.VSTACK('Без этажа'!L3:L1000)=A40)))+SUM(_xlfn.FILTER(_xlfn.VSTACK('Без этажа'!J3:J1000),(_xlfn.VSTACK('Без этажа'!K3:K1000)=A40)+(_xlfn.VSTACK('Без этажа'!L3:L1000)=A40))),0)} -> 0 | D40: =C40*1.1 -> 0 | E40: {=IFERROR(SUM(_xlfn.FILTER((_xlfn.VSTACK('Без этажа'!D3:D1000)*1.005*((_xlfn.VSTACK('Без этажа'!D3:D1000))-(-32))*1.2/3600),(_xlfn.VSTACK('Без этажа'!K3:K1000)=A40)+(_xlfn.VSTACK('Без этажа'!L3:L1000)=A40))),0)} -> 0 | L40: =J40+K40 -> 0
A41: - | B41: {=IFERROR(_xlfn.TEXTJOIN(", ",TRUE,_xlfn.UNIQUE(_xlfn.FILTER(_xlfn.VSTACK('Без этажа'!B3:B1000),(_xlfn.VSTACK('Без этажа'!K3:K1000)=A41)+(_xlfn.VSTACK('Без этажа'!L3:L1000)=A41)))),"Не найдено")} -> 0 | C41: {=IFERROR(SUM(_xlfn.FILTER(_xlfn.VSTACK('Без этажа'!I3:I1000),(_xlfn.VSTACK('Без этажа'!K3:K1000)=A41)+(_xlfn.VSTACK('Без этажа'!L3:L1000)=A41)))+SUM(_xlfn.FILTER(_xlfn.VSTACK('Без этажа'!J3:J1000),(_xlfn.VSTACK('Без этажа'!K3:K1000)=A41)+(_xlfn.VSTACK('Без этажа'!L3:L1000)=A41))),0)} -> 0 | D41: =C41*1.1 -> 0 | E41: {=IFERROR(SUM(_xlfn.FILTER((_xlfn.VSTACK('Без этажа'!D3:D1000)*1.005*((_xlfn.VSTACK('Без этажа'!D3:D1000))-(-32))*1.2/3600),(_xlfn.VSTACK('Без этажа'!K3:K1000)=A41)+(_xlfn.VSTACK('Без этажа'!L3:L1000)=A41))),0)} -> 0 | L41: =J41+K41 -> 0
...

Sheet Подборы
A1: Система | B1: Зона обслуживания | C1: Расход с запасом м3\ч | D1: Потери общие | E1: Тип вентилятора | F1: Климатическое исполнение | G1: Последовательность элементов | H1: Секция нагрева | I1: Кол-во секций нагрева | J1: Температура наружного воздуха ХПГ | K1: Температура приточного воздуха ХПГ | L1: Шумоглушитель | M1: Примечание
A3: ='Системы'!A3 -> 0 | C3: ='Системы'!D3 -> 0 | D3: ='Системы'!L3 -> 0
A4: ='Системы'!A4 -> 0 | C4: ='Системы'!D4 -> 0 | D4: ='Системы'!L4 -> 0
A5: ='Системы'!A5 -> 0 | C5: ='Системы'!D5 -> 0 | D5: ='Системы'!L5 -> 0
A6: ='Системы'!A6 -> 0 | C6: ='Системы'!D6 -> 0 | D6: ='Системы'!L6 -> 0
A7: ='Системы'!A7 -> 0 | C7: ='Системы'!D7 -> 0 | D7: ='Системы'!L7 -> 0
A8: ='Системы'!A8 -> 0 | C8: ='Системы'!D8 -> 0 | D8: ='Системы'!L8 -> 0
A9: ='Системы'!A9 -> 0 | C9: ='Системы'!D9 -> 0 | D9: ='Системы'!L9 -> 0
A10: ='Системы'!A10 -> 0 | C10: ='Системы'!D10 -> 0 | D10: ='Системы'!L10 -> 0
A11: ='Системы'!A11 -> 0 | C11: ='Системы'!D11 -> 0 | D11: ='Системы'!L11 -> 0
A12: ='Системы'!A12 -> 0 | C12: ='Системы'!D12 -> 0 | D12: ='Системы'!L12 -> 0
A13: ='Системы'!A13 -> 0 | C13: ='Системы'!D13 -> 0 | D13: ='Системы'!L13 -> 0
A14: ='Системы'!A14 -> 0 | C14: ='Системы'!D14 -> 0 | D14: ='Системы'!L14 -> 0
... A202: ='Системы'!A202 -> 0 | C202: ='Системы'!D202 -> 0 | D202: ='Системы'!L202 -> 0
